<mujoco model="C-Arm">
  <compiler angle="radian"/>
  <option gravity="0 0 0"/>
  <visual>
    <global elevation="-20"/>
    <quality shadowsize="8192"/>
    <headlight ambient="0.3 0.3 0.3" diffuse="0.6 0.6 0.6" specular="0 0 0"/>
    <rgba haze="0.15 0.25 0.35 1"/>
  </visual>
  <asset>
    <texture type="skybox" builtin="gradient" rgb1="0.3 0.5 0.7" rgb2="0 0 0" width="512" height="3072"/>
    <texture type="2d" name="groundplane" builtin="checker" mark="edge" rgb1="0.2 0.3 0.4" rgb2="0.1 0.2 0.3" markrgb="0.8 0.8 0.8" width="300" height="300"/>
    <material name="black" rgba="0.15 0.15 0.15 1"/>
    <material name="xray" rgba="0.1 0.8 0.1 0.1"/>
    <material name="grey" rgba="0.85 0.8 0.8 1"/>
    <material name="blue" rgba="0.2 0.2 0.8 1"/>
    <material name="groundplane" texture="groundplane" texuniform="true" texrepeat="5 5" reflectance="0.2"/>
    <mesh name="base" file="base.STL" scale="0.35 0.35 0.35"/>
    <mesh name="X_rotation_base" file="X_rotation_base.STL" scale="0.35 0.35 0.35"/>
    <mesh name="Y_rotation_base" file="Y_rotation_base.STL" scale="0.35 0.35 0.35"/>
    <mesh name="X-ray_visual" file="X-ray_visual.STL" scale="0.35 0.35 0.35"/>
    <mesh name="bed" file="bed.STL" scale="0.25 0.25 0.25"/>
  </asset>
  <worldbody>
    <geom name="floor" size="3 3 0.05" pos="0 0 -0.5" type="plane" material="groundplane"/>
    <geom name="base" type="mesh" contype="0" conaffinity="0" density="10" material="grey" mesh="base"/>
    <light pos="0 0.1 2.5" dir="0 0 -1"/>
    <body name="X_rotation_base" pos="-0.071428 -1.71504 0.369075" quat="0.527541 -0.470848 -0.527545 0.470848">
      <joint name="X_rotation" pos="0 0 0" axis="1 0 0" damping="10"/>
      <geom name="X_rotation_base" type="mesh" contype="0" conaffinity="0" density="10" material="grey" mesh="X_rotation_base"/>
      <body name="Y_rotation_base" pos="0.635719 0 0.0175" quat="0.271388 0.652954 0.271388 -0.652954">
        <joint name="Y_rotation" pos="0 0 0" axis="1 0 0" damping="10"/>
        <geom name="Y_rotation_base" type="mesh" contype="0" conaffinity="0" density="10" material="grey" mesh="Y_rotation_base"/>
        <body name="X-ray_visual" pos="0.0175 0.00855256 0.0279742" quat="0.147808 0.989007 0.000617517 0.0041319">
          <geom type="mesh" contype="0" conaffinity="0" density="1" material="xray" mesh="X-ray_visual"/>
        </body>
      </body>
    </body>
    <body name="bed" pos="-0.05102 0 0.25" quat="0.499998 0.5 -0.5 0.500002">
      <joint name="bed sliding" pos="0 0 0" axis="0 0 1" type="slide" damping="10"/>
      <geom name="bed" type="mesh" density="100" material="blue" mesh="bed"/>
    </body>
  </worldbody>
  <actuator>
    <general joint="X_rotation" ctrlrange="-1.5 1.5" biastype="affine" gainprm="20" biasprm="0 -20"/>
    <general joint="Y_rotation" ctrlrange="-0.2 1.9" biastype="affine" gainprm="20" biasprm="0 -20"/>
    <general joint="bed sliding" ctrlrange="0.3 0.7" biastype="affine" gainprm="20" biasprm="0 -20"/>
  </actuator>
</mujoco>
